Workbook

Sheet TargetRealisasiPelatihan
A1: No | B1: Jenis Pelatihan | C1: Target Pelatihan | D1: Realisasi Pelatihan | G1: Realisasi Anggaran | H1: Target | I1: Persen | L1: No | M1: Program Pelatihan | N1: Target Pelatihan | O1: Realisasi Pelatihan | Q1: Kegiatan | R1: Target Pelatihan | S1: Realisasi Pelatihan
A2: 1 | B2: =IFERROR(__xludf.DUMMYFUNCTION("IMPORTRANGE(""https://docs.google.com/spreadsheets/d/1gOuC86bPcKRp_ezDVZ2jC8qSfdua3mXaPnAXFkKjDdI/edit?gid=1300176874#gid=1300176874"",""TargetRealisasi!B2:D"")"),"PBK") -> PBK | C2: =IFERROR(__xludf.DUMMYFUNCTION("""COMPUTED_VALUE"""),576.0) -> 576 | D2: =IFERROR(__xludf.DUMMYFUNCTION("""COMPUTED_VALUE"""),284.0) -> 284 | G2: =IFERROR(__xludf.DUMMYFUNCTION("IMPORTRANGE(""https://docs.google.com/spreadsheets/d/1gOuC86bPcKRp_ezDVZ2jC8qSfdua3mXaPnAXFkKjDdI/edit?gid=1300176874#gid=1300176874"",""TargetRealisasi!F2:H"")"),"Pagu (My Intress)") -> Pagu (My Intress) | H2: =IFERROR(__xludf.DUMMYFUNCTION("""COMPUTED_VALUE"""),5.8460407E10) -> 58460407000 | I2: =IFERROR(__xludf.DUMMYFUNCTION("""COMPUTED_VALUE"""),1.0) -> 1 | L2: 1 | M2: =IFERROR(__xludf.DUMMYFUNCTION("IMPORTRANGE(""https://docs.google.com/spreadsheets/d/1gOuC86bPcKRp_ezDVZ2jC8qSfdua3mXaPnAXFkKjDdI/edit?gid=1300176874#gid=1300176874"",""TargetRealisasi!L2:N"")"),"Sertifikasi") -> Sertifikasi | N2: =IFERROR(__xludf.DUMMYFUNCTION("""COMPUTED_VALUE"""),1728.0) -> 1728 | O2: =IFERROR(__xludf.DUMMYFUNCTION("""COMPUTED_VALUE"""),1459.0) -> 1459 | Q2: =IFERROR(__xludf.DUMMYFUNCTION("IMPORTRANGE(""https://docs.google.com/spreadsheets/d/1gOuC86bPcKRp_ezDVZ2jC8qSfdua3mXaPnAXFkKjDdI/edit?gid=1300176874#gid=1300176874"",""TargetRealisasi!P2:R"")"),"4053 [Pengembangan Sistem dan Pelaksanaan Sertifikasi Kompetensi Profesi Binalavotas") -> 4053 [Pengembangan Sistem dan Pelaksanaan Sertifikasi Kompetensi Profesi Binalavotas | R2: =IFERROR(__xludf.DUMMYFUNCTION("""COMPUTED_VALUE"""),3.651418E9) -> 3651418000 | S2: =IFERROR(__xludf.DUMMYFUNCTION("""COMPUTED_VALUE"""),1.859E7) -> 18590000
A3: 2 | B3: =IFERROR(__xludf.DUMMYFUNCTION("""COMPUTED_VALUE"""),"PBL") -> PBL | C3: =IFERROR(__xludf.DUMMYFUNCTION("""COMPUTED_VALUE"""),320.0) -> 320 | D3: =IFERROR(__xludf.DUMMYFUNCTION("""COMPUTED_VALUE"""),78.0) -> 78 | G3: =IFERROR(__xludf.DUMMYFUNCTION("""COMPUTED_VALUE"""),"Pagu Blokir") -> Pagu Blokir | H3: =IFERROR(__xludf.DUMMYFUNCTION("""COMPUTED_VALUE"""),7.4269E7) -> 74269000 | I3: =IFERROR(__xludf.DUMMYFUNCTION("""COMPUTED_VALUE"""),0.0012704153770260272) -> 0.0012704154 | L3: 2 | M3: =IFERROR(__xludf.DUMMYFUNCTION("""COMPUTED_VALUE"""),"Program Bantuan") -> Program Bantuan | Q3: =IFERROR(__xludf.DUMMYFUNCTION("""COMPUTED_VALUE"""),"4057 [Peningkatan Penyelenggaraan Pelatihan Vokasi dan Pemagangan Binalavotas") -> 4057 [Peningkatan Penyelenggaraan Pelatihan Vokasi dan Pemagangan Binalavotas | R3: =IFERROR(__xludf.DUMMYFUNCTION("""COMPUTED_VALUE"""),4.1097245E10) -> 41097245000 | S3: =IFERROR(__xludf.DUMMYFUNCTION("""COMPUTED_VALUE"""),3.22344854E8) -> 322344854
A4: 3 | B4: =IFERROR(__xludf.DUMMYFUNCTION("""COMPUTED_VALUE"""),"TMT") -> TMT | C4: =IFERROR(__xludf.DUMMYFUNCTION("""COMPUTED_VALUE"""),871.0) -> 871 | D4: =IFERROR(__xludf.DUMMYFUNCTION("""COMPUTED_VALUE"""),235.0) -> 235 | G4: =IFERROR(__xludf.DUMMYFUNCTION("""COMPUTED_VALUE"""),"Pagu Setelah Blokir") -> Pagu Setelah Blokir | H4: =IFERROR(__xludf.DUMMYFUNCTION("""COMPUTED_VALUE"""),5.8386138E10) -> 58386138000 | I4: =IFERROR(__xludf.DUMMYFUNCTION("""COMPUTED_VALUE"""),0.998729584622974) -> 0.99872958 | L4: 3 | M4: =IFERROR(__xludf.DUMMYFUNCTION("""COMPUTED_VALUE"""),"Produktivitas") -> Produktivitas | N4: =IFERROR(__xludf.DUMMYFUNCTION("""COMPUTED_VALUE"""),25.0) -> 25 | Q4: =IFERROR(__xludf.DUMMYFUNCTION("""COMPUTED_VALUE"""),"4059 [Pengembangan dan Peningkatan Produktivitas Tenaga Kerja Binalavotas") -> 4059 [Pengembangan dan Peningkatan Produktivitas Tenaga Kerja Binalavotas | R4: =IFERROR(__xludf.DUMMYFUNCTION("""COMPUTED_VALUE"""),1.37864E8) -> 137864000 | S4: =IFERROR(__xludf.DUMMYFUNCTION("""COMPUTED_VALUE"""),0.0) -> 0
A5: 4 | B5: =IFERROR(__xludf.DUMMYFUNCTION("""COMPUTED_VALUE"""),"UPTD BInaan") -> UPTD BInaan | C5: =IFERROR(__xludf.DUMMYFUNCTION("""COMPUTED_VALUE"""),368.0) -> 368 | D5: =IFERROR(__xludf.DUMMYFUNCTION("""COMPUTED_VALUE"""),0.0) -> 0 | G5: =IFERROR(__xludf.DUMMYFUNCTION("""COMPUTED_VALUE"""),"Target Penerimaan PNBP") -> Target Penerimaan PNBP | H5: =IFERROR(__xludf.DUMMYFUNCTION("""COMPUTED_VALUE"""),4.32242E9) -> 4322420000 | I5: =IFERROR(__xludf.DUMMYFUNCTION("""COMPUTED_VALUE"""),1.0) -> 1 | L5: 4 | M5: =IFERROR(__xludf.DUMMYFUNCTION("""COMPUTED_VALUE"""),"Pemagangan") -> Pemagangan | N5: =IFERROR(__xludf.DUMMYFUNCTION("""COMPUTED_VALUE"""),4.0) -> 4 | Q5: =IFERROR(__xludf.DUMMYFUNCTION("""COMPUTED_VALUE"""),"6988 [Dukungan Manajemen Direktorat Jenderal Pembinaan Pelatihan Vokasi dan Produktivitas Tenaga Kerja Binalavotas") -> 6988 [Dukungan Manajemen Direktorat Jenderal Pembinaan Pelatihan Vokasi dan Produktivitas Tenaga Kerja Binalavotas | R5: =IFERROR(__xludf.DUMMYFUNCTION("""COMPUTED_VALUE"""),1.357388E10) -> 13573880000 | S5: =IFERROR(__xludf.DUMMYFUNCTION("""COMPUTED_VALUE"""),4.01980493E8) -> 401980493
A6: 5 | B6: =IFERROR(__xludf.DUMMYFUNCTION("""COMPUTED_VALUE"""),"PFLK ") -> PFLK | C6: =IFERROR(__xludf.DUMMYFUNCTION("""COMPUTED_VALUE"""),5.0) -> 5 | G6: =IFERROR(__xludf.DUMMYFUNCTION("""COMPUTED_VALUE"""),"Realisasi Penerimaan PNBP") -> Realisasi Penerimaan PNBP | H6: =IFERROR(__xludf.DUMMYFUNCTION("""COMPUTED_VALUE"""),1.291859579E9) -> 1291859579 | I6: =IFERROR(__xludf.DUMMYFUNCTION("""COMPUTED_VALUE"""),0.298874144345066) -> 0.29887414
A7: 6 | G7: =IFERROR(__xludf.DUMMYFUNCTION("""COMPUTED_VALUE"""),"Realisasi Minggu Lalu (my Intress)") -> Realisasi Minggu Lalu (my Intress) | H7: =IFERROR(__xludf.DUMMYFUNCTION("""COMPUTED_VALUE"""),1.1909004557E10) -> 11909004557 | I7: =IFERROR(__xludf.DUMMYFUNCTION("""COMPUTED_VALUE"""),0.20371059950027376) -> 0.2037106
A8: 7 | G8: =IFERROR(__xludf.DUMMYFUNCTION("""COMPUTED_VALUE"""),"Capaian Realisasi Minggu Ini") -> Capaian Realisasi Minggu Ini | H8: =IFERROR(__xludf.DUMMYFUNCTION("""COMPUTED_VALUE"""),7.42915347E8) -> 742915347 | I8: =IFERROR(__xludf.DUMMYFUNCTION("""COMPUTED_VALUE"""),0.012708008464600665) -> 0.012708008
A9: 8 | G9: =IFERROR(__xludf.DUMMYFUNCTION("""COMPUTED_VALUE"""),"Total Realisasi") -> Total Realisasi | H9: =IFERROR(__xludf.DUMMYFUNCTION("""COMPUTED_VALUE"""),1.2651919904E10) -> 12651919904 | I9: =IFERROR(__xludf.DUMMYFUNCTION("""COMPUTED_VALUE"""),0.21641860796487442) -> 0.21641861
A10: 9 | G10: =IFERROR(__xludf.DUMMYFUNCTION("""COMPUTED_VALUE"""),"Sisa Pagu (SAKTI)") -> Sisa Pagu (SAKTI) | H10: =IFERROR(__xludf.DUMMYFUNCTION("""COMPUTED_VALUE"""),4.5808487096E10) -> 45808487096 | I10: =IFERROR(__xludf.DUMMYFUNCTION("""COMPUTED_VALUE"""),0.7835813920351256) -> 0.78358139
A11: 10 | S11: =IFERROR(__xludf.DUMMYFUNCTION("""COMPUTED_VALUE"""),7.42915347E8) -> 742915347
A12: 11
A13: 12
A14: 13
A15: 14

Sheet PelatihanData
A1: NO | B1: KEJURUAN | C1: PROGRAM PELATIHAN | D1: JENIS PELATIHAN | E1: TGL MULAI PELATIHAN | F1: TGL SELESAI PELATIHAN | G1: BULAN MULAI PELATIHAN | H1: LULUS | I1: TIDAK LULUS | J1: JUMLAH PESERTA PELATIHAN | K1: PEREMPUAN | L1: LAKI0LAKI
A2: 1 | B2: =IFERROR(__xludf.DUMMYFUNCTION("IMPORTRANGE(""https://docs.google.com/spreadsheets/d/1YM9eKooeCb3MqOvgwh-HJDRUSsIyH2R7PvjYqBnwrQ0/edit?gid=0#gid=0"", ""Pelatihan!B9:AO200"")"),"Listrik") -> Listrik | C2: =IFERROR(__xludf.DUMMYFUNCTION("""COMPUTED_VALUE"""),"Pemasangan Sistim Integrasi Bangunan Cerdas 1") -> Pemasangan Sistim Integrasi Bangunan Cerdas 1 | D2: =IFERROR(__xludf.DUMMYFUNCTION("""COMPUTED_VALUE"""),"PBL") -> PBL | E2: =IFERROR(__xludf.DUMMYFUNCTION("""COMPUTED_VALUE"""),46195.0) -> 46195 | F2: =IFERROR(__xludf.DUMMYFUNCTION("""COMPUTED_VALUE"""),46232.0) -> 46232 | G2: =IFERROR(__xludf.DUMMYFUNCTION("""COMPUTED_VALUE"""),"Juni") -> Juni | H2: =IFERROR(__xludf.DUMMYFUNCTION("""COMPUTED_VALUE"""),4.0) -> 4 | I2: =IFERROR(__xludf.DUMMYFUNCTION("""COMPUTED_VALUE"""),4.0) -> 4 | J2: =IFERROR(__xludf.DUMMYFUNCTION("""COMPUTED_VALUE"""),8.0) -> 8 | K2: =IFERROR(__xludf.DUMMYFUNCTION("""COMPUTED_VALUE"""),1.0) -> 1 | L2: =IFERROR(__xludf.DUMMYFUNCTION("""COMPUTED_VALUE"""),7.0) -> 7
A3: 2 | B3: =IFERROR(__xludf.DUMMYFUNCTION("""COMPUTED_VALUE"""),"Listrik") -> Listrik | C3: =IFERROR(__xludf.DUMMYFUNCTION("""COMPUTED_VALUE"""),"Pemasangan Sistim Integrasi Bangunan Cerdas 2") -> Pemasangan Sistim Integrasi Bangunan Cerdas 2 | D3: =IFERROR(__xludf.DUMMYFUNCTION("""COMPUTED_VALUE"""),"PBL") -> PBL | G3: =IFERROR(__xludf.DUMMYFUNCTION("""COMPUTED_VALUE"""),"") | J3: =IFERROR(__xludf.DUMMYFUNCTION("""COMPUTED_VALUE"""),"")
A4: 3 | B4: =IFERROR(__xludf.DUMMYFUNCTION("""COMPUTED_VALUE"""),"Listrik") -> Listrik | C4: =IFERROR(__xludf.DUMMYFUNCTION("""COMPUTED_VALUE"""),"Pemasangan Sistim Integrasi Bangunan Cerdas 3") -> Pemasangan Sistim Integrasi Bangunan Cerdas 3 | D4: =IFERROR(__xludf.DUMMYFUNCTION("""COMPUTED_VALUE"""),"PBL") -> PBL | G4: =IFERROR(__xludf.DUMMYFUNCTION("""COMPUTED_VALUE"""),"") | J4: =IFERROR(__xludf.DUMMYFUNCTION("""COMPUTED_VALUE"""),"")
A5: 4 | B5: =IFERROR(__xludf.DUMMYFUNCTION("""COMPUTED_VALUE"""),"Listrik") -> Listrik | C5: =IFERROR(__xludf.DUMMYFUNCTION("""COMPUTED_VALUE"""),"Pemasangan Sistim Integrasi Bangunan Cerdas 4") -> Pemasangan Sistim Integrasi Bangunan Cerdas 4 | D5: =IFERROR(__xludf.DUMMYFUNCTION("""COMPUTED_VALUE"""),"PBL") -> PBL | G5: =IFERROR(__xludf.DUMMYFUNCTION("""COMPUTED_VALUE"""),"") | J5: =IFERROR(__xludf.DUMMYFUNCTION("""COMPUTED_VALUE"""),"")
A6: 5 | B6: =IFERROR(__xludf.DUMMYFUNCTION("""COMPUTED_VALUE"""),"Listrik") -> Listrik | C6: =IFERROR(__xludf.DUMMYFUNCTION("""COMPUTED_VALUE"""),"Pemasangan Sistim Integrasi Bangunan Cerdas 5") -> Pemasangan Sistim Integrasi Bangunan Cerdas 5 | D6: =IFERROR(__xludf.DUMMYFUNCTION("""COMPUTED_VALUE"""),"PBL") -> PBL | G6: =IFERROR(__xludf.DUMMYFUNCTION("""COMPUTED_VALUE"""),"") | J6: =IFERROR(__xludf.DUMMYFUNCTION("""COMPUTED_VALUE"""),"")
A7: 6 | B7: =IFERROR(__xludf.DUMMYFUNCTION("""COMPUTED_VALUE"""),"Elektronika") -> Elektronika | C7: =IFERROR(__xludf.DUMMYFUNCTION("""COMPUTED_VALUE"""),"Smart Farming 1") -> Smart Farming 1 | D7: =IFERROR(__xludf.DUMMYFUNCTION("""COMPUTED_VALUE"""),"PBL") -> PBL | G7: =IFERROR(__xludf.DUMMYFUNCTION("""COMPUTED_VALUE"""),"") | J7: =IFERROR(__xludf.DUMMYFUNCTION("""COMPUTED_VALUE"""),"")
A8: 7 | B8: =IFERROR(__xludf.DUMMYFUNCTION("""COMPUTED_VALUE"""),"Elektronika") -> Elektronika | C8: =IFERROR(__xludf.DUMMYFUNCTION("""COMPUTED_VALUE"""),"Smart Farming 2") -> Smart Farming 2 | D8: =IFERROR(__xludf.DUMMYFUNCTION("""COMPUTED_VALUE"""),"PBL") -> PBL | G8: =IFERROR(__xludf.DUMMYFUNCTION("""COMPUTED_VALUE"""),"") | J8: =IFERROR(__xludf.DUMMYFUNCTION("""COMPUTED_VALUE"""),"")
A9: 8 | B9: =IFERROR(__xludf.DUMMYFUNCTION("""COMPUTED_VALUE"""),"Elektronika") -> Elektronika | C9: =IFERROR(__xludf.DUMMYFUNCTION("""COMPUTED_VALUE"""),"Smart Farming 3") -> Smart Farming 3 | D9: =IFERROR(__xludf.DUMMYFUNCTION("""COMPUTED_VALUE"""),"PBL") -> PBL | G9: =IFERROR(__xludf.DUMMYFUNCTION("""COMPUTED_VALUE"""),"") | J9: =IFERROR(__xludf.DUMMYFUNCTION("""COMPUTED_VALUE"""),"")
A10: 9 | B10: =IFERROR(__xludf.DUMMYFUNCTION("""COMPUTED_VALUE"""),"Elektronika") -> Elektronika | C10: =IFERROR(__xludf.DUMMYFUNCTION("""COMPUTED_VALUE"""),"Smart Farming 4") -> Smart Farming 4 | D10: =IFERROR(__xludf.DUMMYFUNCTION("""COMPUTED_VALUE"""),"PBL") -> PBL | G10: =IFERROR(__xludf.DUMMYFUNCTION("""COMPUTED_VALUE"""),"") | J10: =IFERROR(__xludf.DUMMYFUNCTION("""COMPUTED_VALUE"""),"")
A11: 10 | B11: =IFERROR(__xludf.DUMMYFUNCTION("""COMPUTED_VALUE"""),"Bisnis dan Manajemen") -> Bisnis dan Manajemen | C11: =IFERROR(__xludf.DUMMYFUNCTION("""COMPUTED_VALUE"""),"Digital Office Administration Berbasis Google Workspace 1") -> Digital Office Administration Berbasis Google Workspace 1 | D11: =IFERROR(__xludf.DUMMYFUNCTION("""COMPUTED_VALUE"""),"PBL") -> PBL | E11: =IFERROR(__xludf.DUMMYFUNCTION("""COMPUTED_VALUE"""),46113.0) -> 46113 | F11: =IFERROR(__xludf.DUMMYFUNCTION("""COMPUTED_VALUE"""),46154.0) -> 46154 | G11: =IFERROR(__xludf.DUMMYFUNCTION("""COMPUTED_VALUE"""),"April") -> April | H11: =IFERROR(__xludf.DUMMYFUNCTION("""COMPUTED_VALUE"""),11.0) -> 11 | I11: =IFERROR(__xludf.DUMMYFUNCTION("""COMPUTED_VALUE"""),1.0) -> 1 | J11: =IFERROR(__xludf.DUMMYFUNCTION("""COMPUTED_VALUE"""),12.0) -> 12 | K11: =IFERROR(__xludf.DUMMYFUNCTION("""COMPUTED_VALUE"""),10.0) -> 10 | L11: =IFERROR(__xludf.DUMMYFUNCTION("""COMPUTED_VALUE"""),2.0) -> 2
A12: 11 | B12: =IFERROR(__xludf.DUMMYFUNCTION("""COMPUTED_VALUE"""),"Bisnis dan Manajemen") -> Bisnis dan Manajemen | C12: =IFERROR(__xludf.DUMMYFUNCTION("""COMPUTED_VALUE"""),"Digital Office Administration Berbasis Google Workspace 2") -> Digital Office Administration Berbasis Google Workspace 2 | D12: =IFERROR(__xludf.DUMMYFUNCTION("""COMPUTED_VALUE"""),"PBL") -> PBL | E12: =IFERROR(__xludf.DUMMYFUNCTION("""COMPUTED_VALUE"""),46195.0) -> 46195 | F12: =IFERROR(__xludf.DUMMYFUNCTION("""COMPUTED_VALUE"""),46232.0) -> 46232 | G12: =IFERROR(__xludf.DUMMYFUNCTION("""COMPUTED_VALUE"""),"Juni") -> Juni | J12: =IFERROR(__xludf.DUMMYFUNCTION("""COMPUTED_VALUE"""),16.0) -> 16 | K12: =IFERROR(__xludf.DUMMYFUNCTION("""COMPUTED_VALUE"""),13.0) -> 13 | L12: =IFERROR(__xludf.DUMMYFUNCTION("""COMPUTED_VALUE"""),3.0) -> 3
A13: 12 | B13: =IFERROR(__xludf.DUMMYFUNCTION("""COMPUTED_VALUE"""),"Bisnis dan Manajemen") -> Bisnis dan Manajemen | C13: =IFERROR(__xludf.DUMMYFUNCTION("""COMPUTED_VALUE"""),"Digital Office Administration Berbasis Google Workspace 3") -> Digital Office Administration Berbasis Google Workspace 3 | D13: =IFERROR(__xludf.DUMMYFUNCTION("""COMPUTED_VALUE"""),"PBL") -> PBL | E13: =IFERROR(__xludf.DUMMYFUNCTION("""COMPUTED_VALUE"""),46195.0) -> 46195 | F13: =IFERROR(__xludf.DUMMYFUNCTION("""COMPUTED_VALUE"""),46232.0) -> 46232 | G13: =IFERROR(__xludf.DUMMYFUNCTION("""COMPUTED_VALUE"""),"Juni") -> Juni | J13: =IFERROR(__xludf.DUMMYFUNCTION("""COMPUTED_VALUE"""),16.0) -> 16 | K13: =IFERROR(__xludf.DUMMYFUNCTION("""COMPUTED_VALUE"""),11.0) -> 11 | L13: =IFERROR(__xludf.DUMMYFUNCTION("""COMPUTED_VALUE"""),5.0) -> 5
A14: 13 | B14: =IFERROR(__xludf.DUMMYFUNCTION("""COMPUTED_VALUE"""),"Bisnis dan Manajemen") -> Bisnis dan Manajemen | C14: =IFERROR(__xludf.DUMMYFUNCTION("""COMPUTED_VALUE"""),"Digital Office Administration Berbasis Google Workspace 4") -> Digital Office Administration Berbasis Google Workspace 4 | D14: =IFERROR(__xludf.DUMMYFUNCTION("""COMPUTED_VALUE"""),"PBL") -> PBL | G14: =IFERROR(__xludf.DUMMYFUNCTION("""COMPUTED_VALUE"""),"") | J14: =IFERROR(__xludf.DUMMYFUNCTION("""COMPUTED_VALUE"""),"")
A15: 14 | B15: =IFERROR(__xludf.DUMMYFUNCTION("""COMPUTED_VALUE"""),"Bisnis dan Manajemen") -> Bisnis dan Manajemen | C15: =IFERROR(__xludf.DUMMYFUNCTION("""COMPUTED_VALUE"""),"Digital Office Administration Berbasis Google Workspace 5") -> Digital Office Administration Berbasis Google Workspace 5 | D15: =IFERROR(__xludf.DUMMYFUNCTION("""COMPUTED_VALUE"""),"PBL") -> PBL | G15: =IFERROR(__xludf.DUMMYFUNCTION("""COMPUTED_VALUE"""),"") | J15: =IFERROR(__xludf.DUMMYFUNCTION("""COMPUTED_VALUE"""),"")
A16: 15 | B16: =IFERROR(__xludf.DUMMYFUNCTION("""COMPUTED_VALUE"""),"Bisnis dan Manajemen") -> Bisnis dan Manajemen | C16: =IFERROR(__xludf.DUMMYFUNCTION("""COMPUTED_VALUE"""),"Digital Office Administration Berbasis Google Workspace 6") -> Digital Office Administration Berbasis Google Workspace 6 | D16: =IFERROR(__xludf.DUMMYFUNCTION("""COMPUTED_VALUE"""),"PBL") -> PBL | G16: =IFERROR(__xludf.DUMMYFUNCTION("""COMPUTED_VALUE"""),"") | J16: =IFERROR(__xludf.DUMMYFUNCTION("""COMPUTED_VALUE"""),"")
A17: 16 | B17: =IFERROR(__xludf.DUMMYFUNCTION("""COMPUTED_VALUE"""),"Bisnis dan Manajemen") -> Bisnis dan Manajemen | C17: =IFERROR(__xludf.DUMMYFUNCTION("""COMPUTED_VALUE"""),"Optimalisasi Pemasaran Melalui Media Sosial") -> Optimalisasi Pemasaran Melalui Media Sosial | D17: =IFERROR(__xludf.DUMMYFUNCTION("""COMPUTED_VALUE"""),"PBL") -> PBL | G17: =IFERROR(__xludf.DUMMYFUNCTION("""COMPUTED_VALUE"""),"") | J17: =IFERROR(__xludf.DUMMYFUNCTION("""COMPUTED_VALUE"""),"")
A18: 17 | B18: =IFERROR(__xludf.DUMMYFUNCTION("""COMPUTED_VALUE"""),"TIK") -> TIK | C18: =IFERROR(__xludf.DUMMYFUNCTION("""COMPUTED_VALUE"""),"Pengoperasian Tools Generative AI untuk Konten Digital dan Bisnis") -> Pengoperasian Tools Generative AI untuk Konten Digital dan Bisnis | D18: =IFERROR(__xludf.DUMMYFUNCTION("""COMPUTED_VALUE"""),"PBL") -> PBL | E18: =IFERROR(__xludf.DUMMYFUNCTION("""COMPUTED_VALUE"""),46195.0) -> 46195 | F18: =IFERROR(__xludf.DUMMYFUNCTION("""COMPUTED_VALUE"""),46232.0) -> 46232 | G18: =IFERROR(__xludf.DUMMYFUNCTION("""COMPUTED_VALUE"""),"Juni") -> Juni | J18: =IFERROR(__xludf.DUMMYFUNCTION("""COMPUTED_VALUE"""),13.0) -> 13 | K18: =IFERROR(__xludf.DUMMYFUNCTION("""COMPUTED_VALUE"""),8.0) -> 8 | L18: =IFERROR(__xludf.DUMMYFUNCTION("""COMPUTED_VALUE"""),5.0) -> 5
A19: 18 | B19: =IFERROR(__xludf.DUMMYFUNCTION("""COMPUTED_VALUE"""),"TIK") -> TIK | C19: =IFERROR(__xludf.DUMMYFUNCTION("""COMPUTED_VALUE"""),"Pengembangan Web dengan Node JS dan React") -> Pengembangan Web dengan Node JS dan React | D19: =IFERROR(__xludf.DUMMYFUNCTION("""COMPUTED_VALUE"""),"PBL") -> PBL | G19: =IFERROR(__xludf.DUMMYFUNCTION("""COMPUTED_VALUE"""),"") | J19: =IFERROR(__xludf.DUMMYFUNCTION("""COMPUTED_VALUE"""),"")
A20: 19 | B20: =IFERROR(__xludf.DUMMYFUNCTION("""COMPUTED_VALUE"""),"TIK") -> TIK | C20: =IFERROR(__xludf.DUMMYFUNCTION("""COMPUTED_VALUE"""),"Pembuatan Konten Visual untuk Sosial Media 1") -> Pembuatan Konten Visual untuk Sosial Media 1 | D20: =IFERROR(__xludf.DUMMYFUNCTION("""COMPUTED_VALUE"""),"PBL") -> PBL | E20: =IFERROR(__xludf.DUMMYFUNCTION("""COMPUTED_VALUE"""),46195.0) -> 46195 | F20: =IFERROR(__xludf.DUMMYFUNCTION("""COMPUTED_VALUE"""),46232.0) -> 46232 | G20: =IFERROR(__xludf.DUMMYFUNCTION("""COMPUTED_VALUE"""),"Juni") -> Juni | H20: =IFERROR(__xludf.DUMMYFUNCTION("""COMPUTED_VALUE"""),11.0) -> 11 | I20: =IFERROR(__xludf.DUMMYFUNCTION("""COMPUTED_VALUE"""),2.0) -> 2 | J20: =IFERROR(__xludf.DUMMYFUNCTION("""COMPUTED_VALUE"""),13.0) -> 13 | K20: =IFERROR(__xludf.DUMMYFUNCTION("""COMPUTED_VALUE"""),6.0) -> 6 | L20: =IFERROR(__xludf.DUMMYFUNCTION("""COMPUTED_VALUE"""),7.0) -> 7
A21: 20 | B21: =IFERROR(__xludf.DUMMYFUNCTION("""COMPUTED_VALUE"""),"TIK") -> TIK | C21: =IFERROR(__xludf.DUMMYFUNCTION("""COMPUTED_VALUE"""),"Pembuatan Konten Visual untuk Sosial Media 2") -> Pembuatan Konten Visual untuk Sosial Media 2 | D21: =IFERROR(__xludf.DUMMYFUNCTION("""COMPUTED_VALUE"""),"PBL") -> PBL | G21: =IFERROR(__xludf.DUMMYFUNCTION("""COMPUTED_VALUE"""),"") | J21: =IFERROR(__xludf.DUMMYFUNCTION("""COMPUTED_VALUE"""),"")
A22: 21 | B22: =IFERROR(__xludf.DUMMYFUNCTION("""COMPUTED_VALUE"""),"Otomotif") -> Otomotif | C22: =IFERROR(__xludf.DUMMYFUNCTION("""COMPUTED_VALUE"""),"Pemeliharaan Kendaraan Ringan Sistem Injeksi 1") -> Pemeliharaan Kendaraan Ringan Sistem Injeksi 1 | D22: =IFERROR(__xludf.DUMMYFUNCTION("""COMPUTED_VALUE"""),"PBK") -> PBK | E22: =IFERROR(__xludf.DUMMYFUNCTION("""COMPUTED_VALUE"""),46195.0) -> 46195 | F22: =IFERROR(__xludf.DUMMYFUNCTION("""COMPUTED_VALUE"""),46241.0) -> 46241 | G22: =IFERROR(__xludf.DUMMYFUNCTION("""COMPUTED_VALUE"""),"Juni") -> Juni | J22: =IFERROR(__xludf.DUMMYFUNCTION("""COMPUTED_VALUE"""),16.0) -> 16 | L22: =IFERROR(__xludf.DUMMYFUNCTION("""COMPUTED_VALUE"""),16.0) -> 16
A23: 22 | B23: =IFERROR(__xludf.DUMMYFUNCTION("""COMPUTED_VALUE"""),"Otomotif") -> Otomotif | C23: =IFERROR(__xludf.DUMMYFUNCTION("""COMPUTED_VALUE"""),"Servis Sepeda Motor Sistem Injeksi 1") -> Servis Sepeda Motor Sistem Injeksi 1 | D23: =IFERROR(__xludf.DUMMYFUNCTION("""COMPUTED_VALUE"""),"PBK") -> PBK | E23: =IFERROR(__xludf.DUMMYFUNCTION("""COMPUTED_VALUE"""),46195.0) -> 46195 | F23: =IFERROR(__xludf.DUMMYFUNCTION("""COMPUTED_VALUE"""),46241.0) -> 46241 | G23: =IFERROR(__xludf.DUMMYFUNCTION("""COMPUTED_VALUE"""),"Juni") -> Juni | H23: =IFERROR(__xludf.DUMMYFUNCTION("""COMPUTED_VALUE"""),11.0) -> 11 | I23: =IFERROR(__xludf.DUMMYFUNCTION("""COMPUTED_VALUE"""),5.0) -> 5 | J23: =IFERROR(__xludf.DUMMYFUNCTION("""COMPUTED_VALUE"""),16.0) -> 16 | L23: =IFERROR(__xludf.DUMMYFUNCTION("""COMPUTED_VALUE"""),16.0) -> 16
A24: 23 | B24: =IFERROR(__xludf.DUMMYFUNCTION("""COMPUTED_VALUE"""),"Pertambangan") -> Pertambangan | C24: =IFERROR(__xludf.DUMMYFUNCTION("""COMPUTED_VALUE"""),"Operator Truck Excavator 1") -> Operator Truck Excavator 1 | D24: =IFERROR(__xludf.DUMMYFUNCTION("""COMPUTED_VALUE"""),"PBK") -> PBK | E24: =IFERROR(__xludf.DUMMYFUNCTION("""COMPUTED_VALUE"""),46113.0) -> 46113 | F24: =IFERROR(__xludf.DUMMYFUNCTION("""COMPUTED_VALUE"""),46167.0) -> 46167 | G24: =IFERROR(__xludf.DUMMYFUNCTION("""COMPUTED_VALUE"""),"April") -> April | H24: =IFERROR(__xludf.DUMMYFUNCTION("""COMPUTED_VALUE"""),15.0) -> 15 | I24: =IFERROR(__xludf.DUMMYFUNCTION("""COMPUTED_VALUE"""),1.0) -> 1 | J24: =IFERROR(__xludf.DUMMYFUNCTION("""COMPUTED_VALUE"""),16.0) -> 16 | K24: =IFERROR(__xludf.DUMMYFUNCTION("""COMPUTED_VALUE"""),3.0) -> 3 | L24: =IFERROR(__xludf.DUMMYFUNCTION("""COMPUTED_VALUE"""),13.0) -> 13
A25: 24 | B25: =IFERROR(__xludf.DUMMYFUNCTION("""COMPUTED_VALUE"""),"Pertambangan") -> Pertambangan | C25: =IFERROR(__xludf.DUMMYFUNCTION("""COMPUTED_VALUE"""),"Operator Truck Excavator 2") -> Operator Truck Excavator 2 | D25: =IFERROR(__xludf.DUMMYFUNCTION("""COMPUTED_VALUE"""),"PBK") -> PBK | G25: =IFERROR(__xludf.DUMMYFUNCTION("""COMPUTED_VALUE"""),"") | J25: =IFERROR(__xludf.DUMMYFUNCTION("""COMPUTED_VALUE"""),"")
A26: 25 | B26: =IFERROR(__xludf.DUMMYFUNCTION("""COMPUTED_VALUE"""),"Elektronika") -> Elektronika | C26: =IFERROR(__xludf.DUMMYFUNCTION("""COMPUTED_VALUE"""),"Teknisi Telepon Seluler Perangkat Keras 1") -> Teknisi Telepon Seluler Perangkat Keras 1 | D26: =IFERROR(__xludf.DUMMYFUNCTION("""COMPUTED_VALUE"""),"PBK") -> PBK | E26: =IFERROR(__xludf.DUMMYFUNCTION("""COMPUTED_VALUE"""),46195.0) -> 46195 | F26: =IFERROR(__xludf.DUMMYFUNCTION("""COMPUTED_VALUE"""),46239.0) -> 46239 | G26: =IFERROR(__xludf.DUMMYFUNCTION("""COMPUTED_VALUE"""),"Juni") -> Juni | H26: =IFERROR(__xludf.DUMMYFUNCTION("""COMPUTED_VALUE"""),14.0) -> 14 | I26: =IFERROR(__xludf.DUMMYFUNCTION("""COMPUTED_VALUE"""),2.0) -> 2 | J26: =IFERROR(__xludf.DUMMYFUNCTION("""COMPUTED_VALUE"""),16.0) -> 16 | L26: =IFERROR(__xludf.DUMMYFUNCTION("""COMPUTED_VALUE"""),16.0) -> 16
A27: 26 | B27: =IFERROR(__xludf.DUMMYFUNCTION("""COMPUTED_VALUE"""),"Las") -> Las | C27: =IFERROR(__xludf.DUMMYFUNCTION("""COMPUTED_VALUE"""),"Perakitan Komponen Fabrikasi 1") -> Perakitan Komponen Fabrikasi 1 | D27: =IFERROR(__xludf.DUMMYFUNCTION("""COMPUTED_VALUE"""),"PBK") -> PBK | E27: =IFERROR(__xludf.DUMMYFUNCTION("""COMPUTED_VALUE"""),46113.0) -> 46113 | F27: =IFERROR(__xludf.DUMMYFUNCTION("""COMPUTED_VALUE"""),46147.0) -> 46147 | G27: =IFERROR(__xludf.DUMMYFUNCTION("""COMPUTED_VALUE"""),"April") -> April | H27: =IFERROR(__xludf.DUMMYFUNCTION("""COMPUTED_VALUE"""),7.0) -> 7 | I27: =IFERROR(__xludf.DUMMYFUNCTION("""COMPUTED_VALUE"""),0.0) -> 0 | J27: =IFERROR(__xludf.DUMMYFUNCTION("""COMPUTED_VALUE"""),7.0) -> 7 | K27: =IFERROR(__xludf.DUMMYFUNCTION("""COMPUTED_VALUE"""),0.0) -> 0 | L27: =IFERROR(__xludf.DUMMYFUNCTION("""COMPUTED_VALUE"""),7.0) -> 7
A28: 27 | B28: =IFERROR(__xludf.DUMMYFUNCTION("""COMPUTED_VALUE"""),"Las") -> Las | C28: =IFERROR(__xludf.DUMMYFUNCTION("""COMPUTED_VALUE"""),"Perakitan Komponen Fabrikasi 2") -> Perakitan Komponen Fabrikasi 2 | D28: =IFERROR(__xludf.DUMMYFUNCTION("""COMPUTED_VALUE"""),"PBK") -> PBK | E28: =IFERROR(__xludf.DUMMYFUNCTION("""COMPUTED_VALUE"""),46195.0) -> 46195 | F28: =IFERROR(__xludf.DUMMYFUNCTION("""COMPUTED_VALUE"""),46225.0) -> 46225 | G28: =IFERROR(__xludf.DUMMYFUNCTION("""COMPUTED_VALUE"""),"Juni") -> Juni | H28: =IFERROR(__xludf.DUMMYFUNCTION("""COMPUTED_VALUE"""),16.0) -> 16 | I28: =IFERROR(__xludf.DUMMYFUNCTION("""COMPUTED_VALUE"""),0.0) -> 0 | J28: =IFERROR(__xludf.DUMMYFUNCTION("""COMPUTED_VALUE"""),16.0) -> 16 | L28: =IFERROR(__xludf.DUMMYFUNCTION("""COMPUTED_VALUE"""),16.0) -> 16
A29: 28 | B29: =IFERROR(__xludf.DUMMYFUNCTION("""COMPUTED_VALUE"""),"Las") -> Las | C29: =IFERROR(__xludf.DUMMYFUNCTION("""COMPUTED_VALUE"""),"Perakitan Komponen Fabrikasi 3 ") -> Perakitan Komponen Fabrikasi 3 | D29: =IFERROR(__xludf.DUMMYFUNCTION("""COMPUTED_VALUE"""),"PBK") -> PBK | E29: =IFERROR(__xludf.DUMMYFUNCTION("""COMPUTED_VALUE"""),46195.0) -> 46195 | F29: =IFERROR(__xludf.DUMMYFUNCTION("""COMPUTED_VALUE"""),46225.0) -> 46225 | G29: =IFERROR(__xludf.DUMMYFUNCTION("""COMPUTED_VALUE"""),"Juni") -> Juni | H29: =IFERROR(__xludf.DUMMYFUNCTION("""COMPUTED_VALUE"""),15.0) -> 15 | I29: =IFERROR(__xludf.DUMMYFUNCTION("""COMPUTED_VALUE"""),1.0) -> 1 | J29: =IFERROR(__xludf.DUMMYFUNCTION("""COMPUTED_VALUE"""),16.0) -> 16 | L29: =IFERROR(__xludf.DUMMYFUNCTION("""COMPUTED_VALUE"""),16.0) -> 16
A30: 29 | B30: =IFERROR(__xludf.DUMMYFUNCTION("""COMPUTED_VALUE"""),"Bangunan") -> Bangunan | C30: =IFERROR(__xludf.DUMMYFUNCTION("""COMPUTED_VALUE"""),"Juru Gambar Pekerjaan Jalan dan Jembatan 1") -> Juru Gambar Pekerjaan Jalan dan Jembatan 1 | D30: =IFERROR(__xludf.DUMMYFUNCTION("""COMPUTED_VALUE"""),"PBK") -> PBK | E30: =IFERROR(__xludf.DUMMYFUNCTION("""COMPUTED_VALUE"""),46195.0) -> 46195 | F30: =IFERROR(__xludf.DUMMYFUNCTION("""COMPUTED_VALUE"""),46239.0) -> 46239 | G30: =IFERROR(__xludf.DUMMYFUNCTION("""COMPUTED_VALUE"""),"Juni") -> Juni | H30: =IFERROR(__xludf.DUMMYFUNCTION("""COMPUTED_VALUE"""),7.0) -> 7 | I30: =IFERROR(__xludf.DUMMYFUNCTION("""COMPUTED_VALUE"""),2.0) -> 2 | J30: =IFERROR(__xludf.DUMMYFUNCTION("""COMPUTED_VALUE"""),9.0) -> 9 | K30: =IFERROR(__xludf.DUMMYFUNCTION("""COMPUTED_VALUE"""),2.0) -> 2 | L30: =IFERROR(__xludf.DUMMYFUNCTION("""COMPUTED_VALUE"""),7.0) -> 7
A31: 30 | B31: =IFERROR(__xludf.DUMMYFUNCTION("""COMPUTED_VALUE"""),"Bangunan") -> Bangunan | C31: =IFERROR(__xludf.DUMMYFUNCTION("""COMPUTED_VALUE"""),"Juru Ukur (Surveyor) Kualifikasi 3 1") -> Juru Ukur (Surveyor) Kualifikasi 3 1 | D31: =IFERROR(__xludf.DUMMYFUNCTION("""COMPUTED_VALUE"""),"PBK") -> PBK | G31: =IFERROR(__xludf.DUMMYFUNCTION("""COMPUTED_VALUE"""),"") | J31: =IFERROR(__xludf.DUMMYFUNCTION("""COMPUTED_VALUE"""),"")
A32: 31 | B32: =IFERROR(__xludf.DUMMYFUNCTION("""COMPUTED_VALUE"""),"Bangunan") -> Bangunan | C32: =IFERROR(__xludf.DUMMYFUNCTION("""COMPUTED_VALUE"""),"Juru Ukur (Surveyor) Kualifikasi 3 2") -> Juru Ukur (Surveyor) Kualifikasi 3 2 | D32: =IFERROR(__xludf.DUMMYFUNCTION("""COMPUTED_VALUE"""),"PBK") -> PBK | G32: =IFERROR(__xludf.DUMMYFUNCTION("""COMPUTED_VALUE"""),"") | J32: =IFERROR(__xludf.DUMMYFUNCTION("""COMPUTED_VALUE"""),"")
A33: 32 | B33: =IFERROR(__xludf.DUMMYFUNCTION("""COMPUTED_VALUE"""),"Bangunan") -> Bangunan | C33: =IFERROR(__xludf.DUMMYFUNCTION("""COMPUTED_VALUE"""),"Juru Ukur (Surveyor) Kualifikasi 3 3") -> Juru Ukur (Surveyor) Kualifikasi 3 3 | D33: =IFERROR(__xludf.DUMMYFUNCTION("""COMPUTED_VALUE"""),"PBK") -> PBK | G33: =IFERROR(__xludf.DUMMYFUNCTION("""COMPUTED_VALUE"""),"") | J33: =IFERROR(__xludf.DUMMYFUNCTION("""COMPUTED_VALUE"""),"")
A34: 33 | B34: =IFERROR(__xludf.DUMMYFUNCTION("""COMPUTED_VALUE"""),"Bangunan") -> Bangunan | C34: =IFERROR(__xludf.DUMMYFUNCTION("""COMPUTED_VALUE"""),"Konstruksi (Estimator Biaya Jalan)") -> Konstruksi (Estimator Biaya Jalan) | D34: =IFERROR(__xludf.DUMMYFUNCTION("""COMPUTED_VALUE"""),"PBK") -> PBK | G34: =IFERROR(__xludf.DUMMYFUNCTION("""COMPUTED_VALUE"""),"") | J34: =IFERROR(__xludf.DUMMYFUNCTION("""COMPUTED_VALUE"""),"")
A35: 34 | B35: =IFERROR(__xludf.DUMMYFUNCTION("""COMPUTED_VALUE"""),"Kecantikan") -> Kecantikan | C35: =IFERROR(__xludf.DUMMYFUNCTION("""COMPUTED_VALUE"""),"Merias Wajah 1") -> Merias Wajah 1 | D35: =IFERROR(__xludf.DUMMYFUNCTION("""COMPUTED_VALUE"""),"PBK") -> PBK | E35: =IFERROR(__xludf.DUMMYFUNCTION("""COMPUTED_VALUE"""),46113.0) -> 46113 | F35: =IFERROR(__xludf.DUMMYFUNCTION("""COMPUTED_VALUE"""),46141.0) -> 46141 | G35: =IFERROR(__xludf.DUMMYFUNCTION("""COMPUTED_VALUE"""),"April") -> April | H35: =IFERROR(__xludf.DUMMYFUNCTION("""COMPUTED_VALUE"""),10.0) -> 10 | I35: =IFERROR(__xludf.DUMMYFUNCTION("""COMPUTED_VALUE"""),0.0) -> 0 | J35: =IFERROR(__xludf.DUMMYFUNCTION("""COMPUTED_VALUE"""),10.0) -> 10 | K35: =IFERROR(__xludf.DUMMYFUNCTION("""COMPUTED_VALUE"""),10.0) -> 10 | L35: =IFERROR(__xludf.DUMMYFUNCTION("""COMPUTED_VALUE"""),0.0) -> 0
A36: 35 | B36: =IFERROR(__xludf.DUMMYFUNCTION("""COMPUTED_VALUE"""),"Kecantikan") -> Kecantikan | C36: =IFERROR(__xludf.DUMMYFUNCTION("""COMPUTED_VALUE"""),"Merias Wajah 2") -> Merias Wajah 2 | D36: =IFERROR(__xludf.DUMMYFUNCTION("""COMPUTED_VALUE"""),"PBK") -> PBK | E36: =IFERROR(__xludf.DUMMYFUNCTION("""COMPUTED_VALUE"""),46113.0) -> 46113 | F36: =IFERROR(__xludf.DUMMYFUNCTION("""COMPUTED_VALUE"""),46141.0) -> 46141 | G36: =IFERROR(__xludf.DUMMYFUNCTION("""COMPUTED_VALUE"""),"April") -> April | H36: =IFERROR(__xludf.DUMMYFUNCTION("""COMPUTED_VALUE"""),15.0) -> 15 | I36: =IFERROR(__xludf.DUMMYFUNCTION("""COMPUTED_VALUE"""),1.0) -> 1 | J36: =IFERROR(__xludf.DUMMYFUNCTION("""COMPUTED_VALUE"""),16.0) -> 16 | K36: =IFERROR(__xludf.DUMMYFUNCTION("""COMPUTED_VALUE"""),16.0) -> 16 | L36: =IFERROR(__xludf.DUMMYFUNCTION("""COMPUTED_VALUE"""),0.0) -> 0
A37: 36 | B37: =IFERROR(__xludf.DUMMYFUNCTION("""COMPUTED_VALUE"""),"Kecantikan") -> Kecantikan | C37: =IFERROR(__xludf.DUMMYFUNCTION("""COMPUTED_VALUE"""),"Merias Wajah 3") -> Merias Wajah 3 | D37: =IFERROR(__xludf.DUMMYFUNCTION("""COMPUTED_VALUE"""),"PBK") -> PBK | E37: =IFERROR(__xludf.DUMMYFUNCTION("""COMPUTED_VALUE"""),46195.0) -> 46195 | F37: =IFERROR(__xludf.DUMMYFUNCTION("""COMPUTED_VALUE"""),46220.0) -> 46220 | G37: =IFERROR(__xludf.DUMMYFUNCTION("""COMPUTED_VALUE"""),"Juni") -> Juni | H37: =IFERROR(__xludf.DUMMYFUNCTION("""COMPUTED_VALUE"""),16.0) -> 16 | I37: =IFERROR(__xludf.DUMMYFUNCTION("""COMPUTED_VALUE"""),0.0) -> 0 | J37: =IFERROR(__xludf.DUMMYFUNCTION("""COMPUTED_VALUE"""),16.0) -> 16 | K37: =IFERROR(__xludf.DUMMYFUNCTION("""COMPUTED_VALUE"""),16.0) -> 16
A38: 37 | B38: =IFERROR(__xludf.DUMMYFUNCTION("""COMPUTED_VALUE"""),"Kecantikan") -> Kecantikan | C38: =IFERROR(__xludf.DUMMYFUNCTION("""COMPUTED_VALUE"""),"Merias Wajah 4") -> Merias Wajah 4 | D38: =IFERROR(__xludf.DUMMYFUNCTION("""COMPUTED_VALUE"""),"PBK") -> PBK | E38: =IFERROR(__xludf.DUMMYFUNCTION("""COMPUTED_VALUE"""),46195.0) -> 46195 | F38: =IFERROR(__xludf.DUMMYFUNCTION("""COMPUTED_VALUE"""),46220.0) -> 46220 | G38: =IFERROR(__xludf.DUMMYFUNCTION("""COMPUTED_VALUE"""),"Juni") -> Juni | H38: =IFERROR(__xludf.DUMMYFUNCTION("""COMPUTED_VALUE"""),16.0) -> 16 | I38: =IFERROR(__xludf.DUMMYFUNCTION("""COMPUTED_VALUE"""),0.0) -> 0 | J38: =IFERROR(__xludf.DUMMYFUNCTION("""COMPUTED_VALUE"""),16.0) -> 16 | K38: =IFERROR(__xludf.DUMMYFUNCTION("""COMPUTED_VALUE"""),16.0) -> 16
A39: 38 | B39: =IFERROR(__xludf.DUMMYFUNCTION("""COMPUTED_VALUE"""),"Fashion Technology") -> Fashion Technology | C39: =IFERROR(__xludf.DUMMYFUNCTION("""COMPUTED_VALUE"""),"Asisten Pembuat Pakaian 1") -> Asisten Pembuat Pakaian 1 | D39: =IFERROR(__xludf.DUMMYFUNCTION("""COMPUTED_VALUE"""),"PBK") -> PBK | E39: =IFERROR(__xludf.DUMMYFUNCTION("""COMPUTED_VALUE"""),46195.0) -> 46195 | F39: =IFERROR(__xludf.DUMMYFUNCTION("""COMPUTED_VALUE"""),46225.0) -> 46225 | G39: =IFERROR(__xludf.DUMMYFUNCTION("""COMPUTED_VALUE"""),"Juni") -> Juni | H39: =IFERROR(__xludf.DUMMYFUNCTION("""COMPUTED_VALUE"""),16.0) -> 16 | I39: =IFERROR(__xludf.DUMMYFUNCTION("""COMPUTED_VALUE"""),0.0) -> 0 | J39: =IFERROR(__xludf.DUMMYFUNCTION("""COMPUTED_VALUE"""),16.0) -> 16 | K39: =IFERROR(__xludf.DUMMYFUNCTION("""COMPUTED_VALUE"""),16.0) -> 16
A40: 39 | B40: =IFERROR(__xludf.DUMMYFUNCTION("""COMPUTED_VALUE"""),"Fashion Technology") -> Fashion Technology | C40: =IFERROR(__xludf.DUMMYFUNCTION("""COMPUTED_VALUE"""),"Asisten Pembuat Pakaian 2") -> Asisten Pembuat Pakaian 2 | D40: =IFERROR(__xludf.DUMMYFUNCTION("""COMPUTED_VALUE"""),"PBK") -> PBK | G40: =IFERROR(__xludf.DUMMYFUNCTION("""COMPUTED_VALUE"""),"") | J40: =IFERROR(__xludf.DUMMYFUNCTION("""COMPUTED_VALUE"""),16.0) -> 16 | K40: =IFERROR(__xludf.DUMMYFUNCTION("""COMPUTED_VALUE"""),16.0) -> 16
...

Sheet Pelatihan2
A1: Kejuruan | B1: Jumlah Peserta Pelatihan | D1: Gender | E1: Jumlah Peserta Pelatihan | G1: Kabupaten/Kota | H1: Jumlah Peserta Pelatihan | J1: Pendidikan | K1: Jumlah Peserta Pelatihan | M1: Rentang Usia | N1: Jumlah Peserta Pelatihan
A2: =IFERROR(__xludf.DUMMYFUNCTION("importrange(""https://docs.google.com/spreadsheets/d/1d5jZRF54iX3SxYB3XXzNSD7tMPduQMIhRz21oSv_vsU/edit?gid=1253744388#gid=1253744388"",""Data Pelatihan!A2:B20"")"),"Otomotif") -> Otomotif | B2: =IFERROR(__xludf.DUMMYFUNCTION("""COMPUTED_VALUE"""),207.0) -> 207 | D2: =IFERROR(__xludf.DUMMYFUNCTION("importrange(""https://docs.google.com/spreadsheets/d/1d5jZRF54iX3SxYB3XXzNSD7tMPduQMIhRz21oSv_vsU/edit?gid=1253744388#gid=1253744388"",""Data Pelatihan!D2:E6"")"),"P") -> P | E2: =IFERROR(__xludf.DUMMYFUNCTION("""COMPUTED_VALUE"""),1218.0) -> 1218 | G2: =IFERROR(__xludf.DUMMYFUNCTION("importrange(""https://docs.google.com/spreadsheets/d/1d5jZRF54iX3SxYB3XXzNSD7tMPduQMIhRz21oSv_vsU/edit?gid=1253744388#gid=1253744388"",""Data Pelatihan!G2:H25"")"),"") | H2: =IFERROR(__xludf.DUMMYFUNCTION("""COMPUTED_VALUE"""),"") | J2: =IFERROR(__xludf.DUMMYFUNCTION("importrange(""https://docs.google.com/spreadsheets/d/1d5jZRF54iX3SxYB3XXzNSD7tMPduQMIhRz21oSv_vsU/edit?gid=1253744388#gid=1253744388"",""Data Pelatihan!J2:K10"")"),0.0) -> 0 | K2: =IFERROR(__xludf.DUMMYFUNCTION("""COMPUTED_VALUE"""),641.0) -> 641 | M2: =IFERROR(__xludf.DUMMYFUNCTION("importrange(""https://docs.google.com/spreadsheets/d/1d5jZRF54iX3SxYB3XXzNSD7tMPduQMIhRz21oSv_vsU/edit?gid=1253744388#gid=1253744388"",""Data Pelatihan!M2:N9"")"),"") | N2: =IFERROR(__xludf.DUMMYFUNCTION("""COMPUTED_VALUE"""),"")
A3: =IFERROR(__xludf.DUMMYFUNCTION("""COMPUTED_VALUE"""),"Tata Kecantikan") -> Tata Kecantikan | B3: =IFERROR(__xludf.DUMMYFUNCTION("""COMPUTED_VALUE"""),307.0) -> 307 | D3: =IFERROR(__xludf.DUMMYFUNCTION("""COMPUTED_VALUE"""),"L") -> L | E3: =IFERROR(__xludf.DUMMYFUNCTION("""COMPUTED_VALUE"""),752.0) -> 752 | G3: =IFERROR(__xludf.DUMMYFUNCTION("""COMPUTED_VALUE"""),"Bekerja") -> Bekerja | H3: =IFERROR(__xludf.DUMMYFUNCTION("""COMPUTED_VALUE"""),56.0) -> 56 | J3: =IFERROR(__xludf.DUMMYFUNCTION("""COMPUTED_VALUE"""),1.0) -> 1 | K3: =IFERROR(__xludf.DUMMYFUNCTION("""COMPUTED_VALUE"""),577.0) -> 577 | N3: =IFERROR(__xludf.DUMMYFUNCTION("""COMPUTED_VALUE"""),"")
A4: =IFERROR(__xludf.DUMMYFUNCTION("""COMPUTED_VALUE"""),"Las") -> Las | B4: =IFERROR(__xludf.DUMMYFUNCTION("""COMPUTED_VALUE"""),117.0) -> 117 | D4: =IFERROR(__xludf.DUMMYFUNCTION("""COMPUTED_VALUE""")," ") | E4: =IFERROR(__xludf.DUMMYFUNCTION("""COMPUTED_VALUE"""),1.0) -> 1 | H4: =IFERROR(__xludf.DUMMYFUNCTION("""COMPUTED_VALUE"""),"") | K4: =IFERROR(__xludf.DUMMYFUNCTION("""COMPUTED_VALUE"""),"") | N4: =IFERROR(__xludf.DUMMYFUNCTION("""COMPUTED_VALUE"""),"")
A5: =IFERROR(__xludf.DUMMYFUNCTION("""COMPUTED_VALUE"""),"Teknologi Informasi Dan Komunikasi") -> Teknologi Informasi Dan Komunikasi | B5: =IFERROR(__xludf.DUMMYFUNCTION("""COMPUTED_VALUE"""),349.0) -> 349 | E5: =IFERROR(__xludf.DUMMYFUNCTION("""COMPUTED_VALUE"""),"") | H5: =IFERROR(__xludf.DUMMYFUNCTION("""COMPUTED_VALUE"""),"") | K5: =IFERROR(__xludf.DUMMYFUNCTION("""COMPUTED_VALUE"""),"") | N5: =IFERROR(__xludf.DUMMYFUNCTION("""COMPUTED_VALUE"""),"")
A6: =IFERROR(__xludf.DUMMYFUNCTION("""COMPUTED_VALUE"""),"Bisnis Dan Manajemen") -> Bisnis Dan Manajemen | B6: =IFERROR(__xludf.DUMMYFUNCTION("""COMPUTED_VALUE"""),294.0) -> 294 | E6: =IFERROR(__xludf.DUMMYFUNCTION("""COMPUTED_VALUE"""),"") | H6: =IFERROR(__xludf.DUMMYFUNCTION("""COMPUTED_VALUE"""),"") | K6: =IFERROR(__xludf.DUMMYFUNCTION("""COMPUTED_VALUE"""),"") | N6: =IFERROR(__xludf.DUMMYFUNCTION("""COMPUTED_VALUE"""),"")
A7: =IFERROR(__xludf.DUMMYFUNCTION("""COMPUTED_VALUE"""),"Listrik") -> Listrik | B7: =IFERROR(__xludf.DUMMYFUNCTION("""COMPUTED_VALUE"""),85.0) -> 85 | H7: =IFERROR(__xludf.DUMMYFUNCTION("""COMPUTED_VALUE"""),"") | K7: =IFERROR(__xludf.DUMMYFUNCTION("""COMPUTED_VALUE"""),"") | N7: =IFERROR(__xludf.DUMMYFUNCTION("""COMPUTED_VALUE"""),"")
A8: =IFERROR(__xludf.DUMMYFUNCTION("""COMPUTED_VALUE"""),"Teknologi Pengolahan Agroindustri") -> Teknologi Pengolahan Agroindustri | B8: =IFERROR(__xludf.DUMMYFUNCTION("""COMPUTED_VALUE"""),266.0) -> 266 | D8: Disabilitas | E8: Jumlah Peserta Pelatihan | H8: =IFERROR(__xludf.DUMMYFUNCTION("""COMPUTED_VALUE"""),"") | K8: =IFERROR(__xludf.DUMMYFUNCTION("""COMPUTED_VALUE"""),"") | N8: =IFERROR(__xludf.DUMMYFUNCTION("""COMPUTED_VALUE"""),"")
A9: =IFERROR(__xludf.DUMMYFUNCTION("""COMPUTED_VALUE"""),"Fashion Technology") -> Fashion Technology | B9: =IFERROR(__xludf.DUMMYFUNCTION("""COMPUTED_VALUE"""),128.0) -> 128 | D9: =IFERROR(__xludf.DUMMYFUNCTION("importrange(""https://docs.google.com/spreadsheets/d/1d5jZRF54iX3SxYB3XXzNSD7tMPduQMIhRz21oSv_vsU/edit?gid=1253744388#gid=1253744388"",""Data Pelatihan!D9:E15"")"),1.0) -> 1 | E9: =IFERROR(__xludf.DUMMYFUNCTION("""COMPUTED_VALUE"""),1969.0) -> 1969 | H9: =IFERROR(__xludf.DUMMYFUNCTION("""COMPUTED_VALUE"""),"") | K9: =IFERROR(__xludf.DUMMYFUNCTION("""COMPUTED_VALUE"""),"") | N9: =IFERROR(__xludf.DUMMYFUNCTION("""COMPUTED_VALUE"""),"")
A10: =IFERROR(__xludf.DUMMYFUNCTION("""COMPUTED_VALUE"""),"Konstruksi") -> Konstruksi | B10: =IFERROR(__xludf.DUMMYFUNCTION("""COMPUTED_VALUE"""),12.0) -> 12 | E10: =IFERROR(__xludf.DUMMYFUNCTION("""COMPUTED_VALUE"""),"") | H10: =IFERROR(__xludf.DUMMYFUNCTION("""COMPUTED_VALUE"""),"") | K10: =IFERROR(__xludf.DUMMYFUNCTION("""COMPUTED_VALUE"""),"")
A11: =IFERROR(__xludf.DUMMYFUNCTION("""COMPUTED_VALUE"""),"Processing") -> Processing | B11: =IFERROR(__xludf.DUMMYFUNCTION("""COMPUTED_VALUE"""),16.0) -> 16 | E11: =IFERROR(__xludf.DUMMYFUNCTION("""COMPUTED_VALUE"""),"") | H11: =IFERROR(__xludf.DUMMYFUNCTION("""COMPUTED_VALUE"""),"")
A12: =IFERROR(__xludf.DUMMYFUNCTION("""COMPUTED_VALUE"""),"Pariwisata") -> Pariwisata | B12: =IFERROR(__xludf.DUMMYFUNCTION("""COMPUTED_VALUE"""),142.0) -> 142 | E12: =IFERROR(__xludf.DUMMYFUNCTION("""COMPUTED_VALUE"""),"") | H12: =IFERROR(__xludf.DUMMYFUNCTION("""COMPUTED_VALUE"""),"")
A13: =IFERROR(__xludf.DUMMYFUNCTION("""COMPUTED_VALUE"""),"Pertanian") -> Pertanian | B13: =IFERROR(__xludf.DUMMYFUNCTION("""COMPUTED_VALUE"""),32.0) -> 32 | H13: =IFERROR(__xludf.DUMMYFUNCTION("""COMPUTED_VALUE"""),"")
A14: =IFERROR(__xludf.DUMMYFUNCTION("""COMPUTED_VALUE"""),"Elektronika") -> Elektronika | B14: =IFERROR(__xludf.DUMMYFUNCTION("""COMPUTED_VALUE"""),16.0) -> 16 | H14: =IFERROR(__xludf.DUMMYFUNCTION("""COMPUTED_VALUE"""),"")
A15: =IFERROR(__xludf.DUMMYFUNCTION("""COMPUTED_VALUE"""),"") | B15: =IFERROR(__xludf.DUMMYFUNCTION("""COMPUTED_VALUE"""),"") | H15: =IFERROR(__xludf.DUMMYFUNCTION("""COMPUTED_VALUE"""),"")
B16: =IFERROR(__xludf.DUMMYFUNCTION("""COMPUTED_VALUE"""),"") | H16: =IFERROR(__xludf.DUMMYFUNCTION("""COMPUTED_VALUE"""),"")
B17: =IFERROR(__xludf.DUMMYFUNCTION("""COMPUTED_VALUE"""),"") | H17: =IFERROR(__xludf.DUMMYFUNCTION("""COMPUTED_VALUE"""),"")
B18: =IFERROR(__xludf.DUMMYFUNCTION("""COMPUTED_VALUE"""),"") | H18: =IFERROR(__xludf.DUMMYFUNCTION("""COMPUTED_VALUE"""),"")
B19: =IFERROR(__xludf.DUMMYFUNCTION("""COMPUTED_VALUE"""),"") | H19: =IFERROR(__xludf.DUMMYFUNCTION("""COMPUTED_VALUE"""),"")
B20: =IFERROR(__xludf.DUMMYFUNCTION("""COMPUTED_VALUE"""),"") | H20: =IFERROR(__xludf.DUMMYFUNCTION("""COMPUTED_VALUE"""),"")
H21: =IFERROR(__xludf.DUMMYFUNCTION("""COMPUTED_VALUE"""),"")
H22: =IFERROR(__xludf.DUMMYFUNCTION("""COMPUTED_VALUE"""),"")
H23: =IFERROR(__xludf.DUMMYFUNCTION("""COMPUTED_VALUE"""),"")
H24: =IFERROR(__xludf.DUMMYFUNCTION("""COMPUTED_VALUE"""),"")
H25: =IFERROR(__xludf.DUMMYFUNCTION("""COMPUTED_VALUE"""),"")

Sheet RingkasanPelatihan
A1: JUMLAH PESERTA PELATIHAN | D1: Jumlah Peserta Berdasarkan Kejuruan | G1: Jumlah Peserta Berdasarkan Program | N1: data peserta per bulan (line chart) | Q1: table klasifikasi usia (batang CHART) | T1: tabel berdaarkan kabupaten
A2: Peserta | B2: Total | D2: Kejuruan | E2: Jumlah Peserta | G2: Program | H2: Tanggal Mulai Pelatihan | I2: Tanggal Selesai Pelatihan | J2: Laki-laki | K2: Perempuan | N2: Bulan | O2: Jml Peserta | Q2: Usia | R2: Jml Peserta | T2: Nama Kabupaten | U2: Jumlah Peserta
A3: Laki-Laki | B3: {=_xlfn.XLOOKUP("L",Pelatihan2!D2:D6,Pelatihan2!E2:E6)} -> 752 | D3: {=UNIQUE(Pelatihan2!A2:A25)} -> Otomotif | E3: {=if(D3:D25="","",_xlfn.xlookup(D3:D25,Pelatihan2!$A$2:$A$25,Pelatihan2!$B$2:$B$25))} -> 207 | G3: {=IF(LEN(PelatihanData!C2:C1000), (PelatihanData!C2:C1000), "")} -> Pemasangan Sistim Integrasi Bangunan Cerdas 1 | H3: {=IF(ISBLANK(PelatihanData!E2:E1001), "", TEXT(PelatihanData!E2:E1001, "yyyy-mm-dd"))} -> 2026-06-22 | I3: {=IF(ISBLANK(PelatihanData!F2:F1001), "", TEXT(PelatihanData!F2:F1001, "yyyy-mm-dd"))} -> 2026-07-29 | J3: {=IF(ISBLANK(PelatihanData!L2:L1001), "", PelatihanData!L2:L1001)} -> 7 | K3: {=IF(ISBLANK(PelatihanData!K2:K1001), "", PelatihanData!K2:K1001)} -> 1 | N3: Januari | O3: {=IF(ISBLANK(N3:N50500), "", SUMIF(PelatihanData!$G$2:$G50500, N3:N50500, PelatihanData!$J$2:$J50500) )} -> 0 | Q3: 17-24 tahun | R3: {=if(Q3:Q50500="","",_xlfn.xlookup(Q3:Q50500,Pelatihan2!$M$2:$M$10,Pelatihan2!$N$2:$N$10))} -> #N/A | T3: {=Table15[]}
A4: Perempuan | B4: {=_xlfn.XLOOKUP("P",Pelatihan2!D2:D6,Pelatihan2!E2:E6)} -> 1218 | D4: Tata Kecantikan | E4: 307 | G4: Pemasangan Sistim Integrasi Bangunan Cerdas 2 | N4: Februari | O4: 0 | Q4: 25-28 tahun | R4: #N/A | T4: Bekerja | U4: 56
D5: Las | E5: 117 | G5: Pemasangan Sistim Integrasi Bangunan Cerdas 3 | N5: Maret | O5: 0 | Q5: 29-34 tahun | R5: #N/A
A6: Sarjana | B6: {=_xlfn.xlookup(A6,Pelatihan2!$J$2:$J$10,Pelatihan2!$K$2:$K$10)} -> #N/A | D6: Teknologi Informasi Dan Komunikasi | E6: 349 | G6: Pemasangan Sistim Integrasi Bangunan Cerdas 4 | N6: April | O6: 98 | Q6: 35-40 tahun | R6: #N/A
A7: Diploma | B7: {=_xlfn.xlookup(A7,Pelatihan2!$J$2:$J$10,Pelatihan2!$K$2:$K$10)} -> #N/A | D7: Bisnis Dan Manajemen | E7: 294 | G7: Pemasangan Sistim Integrasi Bangunan Cerdas 5 | N7: Mei | O7: 0 | Q7: Di atas 41 tahun | R7: #N/A
A8: SMA/ SMK | B8: {=_xlfn.xlookup("SMA",Pelatihan2!$J$2:$J$10,Pelatihan2!$K$2:$K$10)} -> #N/A | D8: Listrik | E8: 85 | G8: Smart Farming 1 | N8: Juni | O8: 291
A9: SMP | B9: {=_xlfn.xlookup(A9,Pelatihan2!$J$2:$J$10,Pelatihan2!$K$2:$K$10)} -> #N/A | D9: Teknologi Pengolahan Agroindustri | E9: 266 | G9: Smart Farming 2 | N9: Juli | O9: 192
A10: SD | B10: {=_xlfn.xlookup(A10,Pelatihan2!$J$2:$J$10,Pelatihan2!$K$2:$K$10)} -> #N/A | D10: Fashion Technology | E10: 128 | G10: Smart Farming 3 | N10: Agustus | O10: 0
A11: Disabilitas | B11: {=_xlfn.xlookup(A11,Pelatihan2!D9:D10,Pelatihan2!E9:E10)} -> #N/A | D11: Konstruksi | E11: 12 | G11: Smart Farming 4 | N11: September | O11: 0
A12: Total | B12: =SUM(B3:B4) -> 1970 | D12: Processing | E12: 16 | G12: Digital Office Administration Berbasis Google Workspace 1 | H12: 2026-04-01 | I12: 2026-05-12 | J12: 2 | K12: 10 | N12: Oktober | O12: 0
D13: Pariwisata | E13: 142 | G13: Digital Office Administration Berbasis Google Workspace 2 | H13: 2026-06-22 | I13: 2026-07-29 | J13: 3 | K13: 13 | N13: November | O13: 0
A14: Jumlah Peserta Lulus dan Tidak Lulus | D14: Pertanian | E14: 32 | G14: Digital Office Administration Berbasis Google Workspace 3 | H14: 2026-06-22 | I14: 2026-07-29 | J14: 5 | K14: 11 | N14: Desember | O14: 0
A15: Status Kelulusan | B15: Total Peserta | D15: Elektronika | E15: 16 | G15: Digital Office Administration Berbasis Google Workspace 4
A16: Lulus | B16: =sum(PelatihanData!H2:H50500) -> 428 | G16: Digital Office Administration Berbasis Google Workspace 5
A17: Tudak Lulus | B17: =sum(PelatihanData!I2:I50500) -> 32 | G17: Digital Office Administration Berbasis Google Workspace 6
G18: Optimalisasi Pemasaran Melalui Media Sosial
G19: Pengoperasian Tools Generative AI untuk Konten Digital dan Bisnis | H19: 2026-06-22 | I19: 2026-07-29 | J19: 5 | K19: 8
A20: Jumlah Semua Peserta (DIHOME) | B20: =B3+B4+RingkasanPelatihanUPTD!I3+RingkasanPelatihanUPTD!I4 -> 1970 | G20: Pengembangan Web dengan Node JS dan React
G21: Pembuatan Konten Visual untuk Sosial Media 1 | H21: 2026-06-22 | I21: 2026-07-29 | J21: 7 | K21: 6
G22: Pembuatan Konten Visual untuk Sosial Media 2
G23: Pemeliharaan Kendaraan Ringan Sistem Injeksi 1 | H23: 2026-06-22 | I23: 2026-08-07 | J23: 16
G24: Servis Sepeda Motor Sistem Injeksi 1 | H24: 2026-06-22 | I24: 2026-08-07 | J24: 16
G25: Operator Truck Excavator 1 | H25: 2026-04-01 | I25: 2026-05-25 | J25: 13 | K25: 3
G26: Operator Truck Excavator 2
G27: Teknisi Telepon Seluler Perangkat Keras 1 | H27: 2026-06-22 | I27: 2026-08-05 | J27: 16
G28: Perakitan Komponen Fabrikasi 1 | H28: 2026-04-01 | I28: 2026-05-05 | J28: 7 | K28: 0
G29: Perakitan Komponen Fabrikasi 2 | H29: 2026-06-22 | I29: 2026-07-22 | J29: 16
G30: Perakitan Komponen Fabrikasi 3 | H30: 2026-06-22 | I30: 2026-07-22 | J30: 16
G31: Juru Gambar Pekerjaan Jalan dan Jembatan 1 | H31: 2026-06-22 | I31: 2026-08-05 | J31: 7 | K31: 2
G32: Juru Ukur (Surveyor) Kualifikasi 3 1
G33: Juru Ukur (Surveyor) Kualifikasi 3 2
G34: Juru Ukur (Surveyor) Kualifikasi 3 3
G35: Konstruksi (Estimator Biaya Jalan)
G36: Merias Wajah 1 | H36: 2026-04-01 | I36: 2026-04-29 | J36: 0 | K36: 10
G37: Merias Wajah 2 | H37: 2026-04-01 | I37: 2026-04-29 | J37: 0 | K37: 16
G38: Merias Wajah 3 | H38: 2026-06-22 | I38: 2026-07-17 | K38: 16
G39: Merias Wajah 4 | H39: 2026-06-22 | I39: 2026-07-17 | K39: 16
G40: Asisten Pembuat Pakaian 1 | H40: 2026-06-22 | I40: 2026-07-22 | K40: 16
...

Sheet PelatihanUPTD
A1: =IFERROR(__xludf.DUMMYFUNCTION("QUERY({ {IMPORTRANGE(""https://docs.google.com/spreadsheets/d/1sd5SCH_VG67J2N7wSB4IC6VLcHkLjVGo6yJYuv7-4xA/edit"", ""Sheet1!A1:Q1"") , ""Daerah""}; {IMPORTRANGE(""https://docs.google.com/spreadsheets/d/1sd5SCH_VG67J2N7wSB4IC6VLcHkLjVGo6yJYuv7-4xA/edit"&""", ""Sheet1!A2:Q"") , ARRAYFORMULA(IF(LEN(IMPORTRANGE(""https://docs.google.com/spreadsheets/d/1sd5SCH_VG67J2N7wSB4IC6VLcHkLjVGo6yJYuv7-4xA/edit"", ""Sheet1!A2:A"")), ""Kolaka"", """"))}; {IMPORTRANGE(""https://docs.google.com/spreadsheets/d/1BFAaaNhcK"&"Qpx44EyFvgho96y-idiI9drBXsc9k3IHBc/edit?gid=0#gid=0"", ""Sheet1!A2:Q"") , ARRAYFORMULA(IF(LEN(IMPORTRANGE(""https://docs.google.com/spreadsheets/d/1BFAaaNhcKQpx44EyFvgho96y-idiI9drBXsc9k3IHBc/edit?gid=0#gid=0"", ""Sheet1!A2:A"")), ""Kolaka Utara"", """"))"&"}; {IMPORTRANGE(""https://docs.google.com/spreadsheets/d/1AEcJ2aPbOAhLzeebFmUyeb8lkDwvzAVWOS1_e-83UJg/edit?gid=0#gid=0"", ""Sheet1!A2:Q"") , ARRAYFORMULA(IF(LEN(IMPORTRANGE(""https://docs.google.com/spreadsheets/d/1AEcJ2aPbOAhLzeebFmUyeb8lkDwvzAVWOS1_e-"&"83UJg/edit?gid=0#gid=0"", ""Sheet1!A2:A"")), ""Konawe Selatan"", """"))}; {IMPORTRANGE(""https://docs.google.com/spreadsheets/d/1dl9sgrfqat4UnqbaGDiCZPH9HQhFFcUyDIVQxUBroEU/edit?gid=0#gid=0"", ""Sheet1!A2:Q"") , ARRAYFORMULA(IF(LEN(IMPORTRANGE(""https:/"&"/docs.google.com/spreadsheets/d/1dl9sgrfqat4UnqbaGDiCZPH9HQhFFcUyDIVQxUBroEU/edit?gid=0#gid=0"", ""Sheet1!A2:A"")), ""Konawe Utara"", """"))}; {IMPORTRANGE(""https://docs.google.com/spreadsheets/d/130XdVJPPKI4G-5CbKM02M4arXT51kMYPokkkngjU9fI/edit?gid=0#"&"gid=0"", ""Sheet1!A2:Q"") , ARRAYFORMULA(IF(LEN(IMPORTRANGE(""https://docs.google.com/spreadsheets/d/130XdVJPPKI4G-5CbKM02M4arXT51kMYPokkkngjU9fI/edit?gid=0#gid=0"", ""Sheet1!A2:A"")), ""Buton"", """"))} }, ""SELECT * WHERE Col2 IS NOT NULL AND Col2 <> ''"&""")"),"NO") -> NO | B1: =IFERROR(__xludf.DUMMYFUNCTION("""COMPUTED_VALUE"""),"KEJURUAN") -> KEJURUAN | C1: =IFERROR(__xludf.DUMMYFUNCTION("""COMPUTED_VALUE"""),"PROGRAM PELATIHAN") -> PROGRAM PELATIHAN | D1: =IFERROR(__xludf.DUMMYFUNCTION("""COMPUTED_VALUE"""),"JUMLAH PESERTA PELATIHAN") -> JUMLAH PESERTA PELATIHAN | E1: =IFERROR(__xludf.DUMMYFUNCTION("""COMPUTED_VALUE"""),"PEREMPUAN") -> PEREMPUAN | F1: =IFERROR(__xludf.DUMMYFUNCTION("""COMPUTED_VALUE"""),"LAKI-LAKI") -> LAKI-LAKI | G1: =IFERROR(__xludf.DUMMYFUNCTION("""COMPUTED_VALUE"""),"S1/D4") -> S1/D4 | H1: =IFERROR(__xludf.DUMMYFUNCTION("""COMPUTED_VALUE"""),"D3") -> D3 | I1: =IFERROR(__xludf.DUMMYFUNCTION("""COMPUTED_VALUE"""),"SMA / SMK") -> SMA / SMK | J1: =IFERROR(__xludf.DUMMYFUNCTION("""COMPUTED_VALUE"""),"SMP") -> SMP | K1: =IFERROR(__xludf.DUMMYFUNCTION("""COMPUTED_VALUE"""),"SD") -> SD | L1: =IFERROR(__xludf.DUMMYFUNCTION("""COMPUTED_VALUE"""),"DISABILITAS") -> DISABILITAS | M1: =IFERROR(__xludf.DUMMYFUNCTION("""COMPUTED_VALUE"""),"U 17-24") -> U 17-24 | N1: =IFERROR(__xludf.DUMMYFUNCTION("""COMPUTED_VALUE""")," U 25-28") -> U 25-28 | O1: =IFERROR(__xludf.DUMMYFUNCTION("""COMPUTED_VALUE"""),"U 29-34") -> U 29-34 | P1: =IFERROR(__xludf.DUMMYFUNCTION("""COMPUTED_VALUE"""),"U 35-40") -> U 35-40 | Q1: =IFERROR(__xludf.DUMMYFUNCTION("""COMPUTED_VALUE"""),"U 41-dst") -> U 41-dst | R1: =IFERROR(__xludf.DUMMYFUNCTION("""COMPUTED_VALUE"""),"Daerah") -> Daerah
A2: =IFERROR(__xludf.DUMMYFUNCTION("""COMPUTED_VALUE"""),1.0) -> 1 | B2: =IFERROR(__xludf.DUMMYFUNCTION("""COMPUTED_VALUE"""),"TIK") -> TIK | C2: =IFERROR(__xludf.DUMMYFUNCTION("""COMPUTED_VALUE"""),"Computer Operator Assistant") -> Computer Operator Assistant | R2: =IFERROR(__xludf.DUMMYFUNCTION("""COMPUTED_VALUE"""),"Kolaka") -> Kolaka
A3: =IFERROR(__xludf.DUMMYFUNCTION("""COMPUTED_VALUE"""),2.0) -> 2 | B3: =IFERROR(__xludf.DUMMYFUNCTION("""COMPUTED_VALUE"""),"Fashion Technology") -> Fashion Technology | C3: =IFERROR(__xludf.DUMMYFUNCTION("""COMPUTED_VALUE"""),"Menjahit Pakaian Wanita Dewasa") -> Menjahit Pakaian Wanita Dewasa | R3: =IFERROR(__xludf.DUMMYFUNCTION("""COMPUTED_VALUE"""),"Kolaka") -> Kolaka
A4: =IFERROR(__xludf.DUMMYFUNCTION("""COMPUTED_VALUE"""),3.0) -> 3 | B4: =IFERROR(__xludf.DUMMYFUNCTION("""COMPUTED_VALUE"""),"TIK") -> TIK | C4: =IFERROR(__xludf.DUMMYFUNCTION("""COMPUTED_VALUE"""),"Pengelola Administrasi Perkantoran") -> Pengelola Administrasi Perkantoran | R4: =IFERROR(__xludf.DUMMYFUNCTION("""COMPUTED_VALUE"""),"Kolaka") -> Kolaka
A5: =IFERROR(__xludf.DUMMYFUNCTION("""COMPUTED_VALUE"""),4.0) -> 4 | B5: =IFERROR(__xludf.DUMMYFUNCTION("""COMPUTED_VALUE"""),"Bangunan") -> Bangunan | C5: =IFERROR(__xludf.DUMMYFUNCTION("""COMPUTED_VALUE"""),"Juru Ukur (Surveyor) Kualifikasi 3") -> Juru Ukur (Surveyor) Kualifikasi 3 | R5: =IFERROR(__xludf.DUMMYFUNCTION("""COMPUTED_VALUE"""),"Kolaka") -> Kolaka
A6: =IFERROR(__xludf.DUMMYFUNCTION("""COMPUTED_VALUE"""),5.0) -> 5 | B6: =IFERROR(__xludf.DUMMYFUNCTION("""COMPUTED_VALUE"""),"Las") -> Las | C6: =IFERROR(__xludf.DUMMYFUNCTION("""COMPUTED_VALUE"""),"Fabrikasi 1") -> Fabrikasi 1 | R6: =IFERROR(__xludf.DUMMYFUNCTION("""COMPUTED_VALUE"""),"Kolaka") -> Kolaka
A7: =IFERROR(__xludf.DUMMYFUNCTION("""COMPUTED_VALUE"""),6.0) -> 6 | B7: =IFERROR(__xludf.DUMMYFUNCTION("""COMPUTED_VALUE"""),"Las") -> Las | C7: =IFERROR(__xludf.DUMMYFUNCTION("""COMPUTED_VALUE"""),"Fabrikasi 2") -> Fabrikasi 2 | R7: =IFERROR(__xludf.DUMMYFUNCTION("""COMPUTED_VALUE"""),"Kolaka") -> Kolaka
A8: =IFERROR(__xludf.DUMMYFUNCTION("""COMPUTED_VALUE"""),7.0) -> 7 | B8: =IFERROR(__xludf.DUMMYFUNCTION("""COMPUTED_VALUE"""),"Teknologi Pengolahan Pertanian") -> Teknologi Pengolahan Pertanian | C8: =IFERROR(__xludf.DUMMYFUNCTION("""COMPUTED_VALUE"""),"Pembuatan Roti dan Kue 1") -> Pembuatan Roti dan Kue 1 | R8: =IFERROR(__xludf.DUMMYFUNCTION("""COMPUTED_VALUE"""),"Kolaka") -> Kolaka
A9: =IFERROR(__xludf.DUMMYFUNCTION("""COMPUTED_VALUE"""),8.0) -> 8 | B9: =IFERROR(__xludf.DUMMYFUNCTION("""COMPUTED_VALUE"""),"Teknologi Pengolahan Pertanian") -> Teknologi Pengolahan Pertanian | C9: =IFERROR(__xludf.DUMMYFUNCTION("""COMPUTED_VALUE"""),"Pembuatan Roti dan Kue 2") -> Pembuatan Roti dan Kue 2 | R9: =IFERROR(__xludf.DUMMYFUNCTION("""COMPUTED_VALUE"""),"Kolaka") -> Kolaka
A10: =IFERROR(__xludf.DUMMYFUNCTION("""COMPUTED_VALUE"""),1.0) -> 1 | B10: =IFERROR(__xludf.DUMMYFUNCTION("""COMPUTED_VALUE"""),"TIK") -> TIK | C10: =IFERROR(__xludf.DUMMYFUNCTION("""COMPUTED_VALUE"""),"Computer Operator Assitant") -> Computer Operator Assitant | R10: =IFERROR(__xludf.DUMMYFUNCTION("""COMPUTED_VALUE"""),"Kolaka Utara") -> Kolaka Utara
A11: =IFERROR(__xludf.DUMMYFUNCTION("""COMPUTED_VALUE"""),2.0) -> 2 | B11: =IFERROR(__xludf.DUMMYFUNCTION("""COMPUTED_VALUE"""),"Fashion Technology") -> Fashion Technology | C11: =IFERROR(__xludf.DUMMYFUNCTION("""COMPUTED_VALUE"""),"Menjahit Pakaian Wanita Dewasa") -> Menjahit Pakaian Wanita Dewasa | R11: =IFERROR(__xludf.DUMMYFUNCTION("""COMPUTED_VALUE"""),"Kolaka Utara") -> Kolaka Utara
A12: =IFERROR(__xludf.DUMMYFUNCTION("""COMPUTED_VALUE"""),3.0) -> 3 | B12: =IFERROR(__xludf.DUMMYFUNCTION("""COMPUTED_VALUE"""),"Las") -> Las | C12: =IFERROR(__xludf.DUMMYFUNCTION("""COMPUTED_VALUE"""),"Fabrikasi 1") -> Fabrikasi 1 | R12: =IFERROR(__xludf.DUMMYFUNCTION("""COMPUTED_VALUE"""),"Kolaka Utara") -> Kolaka Utara
A13: =IFERROR(__xludf.DUMMYFUNCTION("""COMPUTED_VALUE"""),4.0) -> 4 | B13: =IFERROR(__xludf.DUMMYFUNCTION("""COMPUTED_VALUE"""),"Las") -> Las | C13: =IFERROR(__xludf.DUMMYFUNCTION("""COMPUTED_VALUE"""),"Fabrikasi 2") -> Fabrikasi 2 | R13: =IFERROR(__xludf.DUMMYFUNCTION("""COMPUTED_VALUE"""),"Kolaka Utara") -> Kolaka Utara
A14: =IFERROR(__xludf.DUMMYFUNCTION("""COMPUTED_VALUE"""),1.0) -> 1 | B14: =IFERROR(__xludf.DUMMYFUNCTION("""COMPUTED_VALUE"""),"TIK") -> TIK | C14: =IFERROR(__xludf.DUMMYFUNCTION("""COMPUTED_VALUE"""),"Computer Operator Assistant") -> Computer Operator Assistant | R14: =IFERROR(__xludf.DUMMYFUNCTION("""COMPUTED_VALUE"""),"Konawe Selatan") -> Konawe Selatan
A15: =IFERROR(__xludf.DUMMYFUNCTION("""COMPUTED_VALUE"""),2.0) -> 2 | B15: =IFERROR(__xludf.DUMMYFUNCTION("""COMPUTED_VALUE"""),"Fashion Technology") -> Fashion Technology | C15: =IFERROR(__xludf.DUMMYFUNCTION("""COMPUTED_VALUE"""),"Menjahit Pakaian Wanita Dewasa") -> Menjahit Pakaian Wanita Dewasa | R15: =IFERROR(__xludf.DUMMYFUNCTION("""COMPUTED_VALUE"""),"Konawe Selatan") -> Konawe Selatan
A16: =IFERROR(__xludf.DUMMYFUNCTION("""COMPUTED_VALUE"""),3.0) -> 3 | B16: =IFERROR(__xludf.DUMMYFUNCTION("""COMPUTED_VALUE"""),"Las") -> Las | C16: =IFERROR(__xludf.DUMMYFUNCTION("""COMPUTED_VALUE"""),"Fabrikasi 1") -> Fabrikasi 1 | R16: =IFERROR(__xludf.DUMMYFUNCTION("""COMPUTED_VALUE"""),"Konawe Selatan") -> Konawe Selatan
A17: =IFERROR(__xludf.DUMMYFUNCTION("""COMPUTED_VALUE"""),4.0) -> 4 | B17: =IFERROR(__xludf.DUMMYFUNCTION("""COMPUTED_VALUE"""),"Las") -> Las | C17: =IFERROR(__xludf.DUMMYFUNCTION("""COMPUTED_VALUE"""),"Fabrikasi 2") -> Fabrikasi 2 | R17: =IFERROR(__xludf.DUMMYFUNCTION("""COMPUTED_VALUE"""),"Konawe Selatan") -> Konawe Selatan
A18: =IFERROR(__xludf.DUMMYFUNCTION("""COMPUTED_VALUE"""),5.0) -> 5 | B18: =IFERROR(__xludf.DUMMYFUNCTION("""COMPUTED_VALUE"""),"Teknologi Pengolahan Pertanian") -> Teknologi Pengolahan Pertanian | C18: =IFERROR(__xludf.DUMMYFUNCTION("""COMPUTED_VALUE"""),"Pembuatan Roti dan Kue") -> Pembuatan Roti dan Kue | R18: =IFERROR(__xludf.DUMMYFUNCTION("""COMPUTED_VALUE"""),"Konawe Selatan") -> Konawe Selatan
A19: =IFERROR(__xludf.DUMMYFUNCTION("""COMPUTED_VALUE"""),1.0) -> 1 | B19: =IFERROR(__xludf.DUMMYFUNCTION("""COMPUTED_VALUE"""),"Fashion Technology") -> Fashion Technology | C19: =IFERROR(__xludf.DUMMYFUNCTION("""COMPUTED_VALUE"""),"Menjahit Pakaian Wanita Dewasa") -> Menjahit Pakaian Wanita Dewasa | R19: =IFERROR(__xludf.DUMMYFUNCTION("""COMPUTED_VALUE"""),"Konawe Utara") -> Konawe Utara
A20: =IFERROR(__xludf.DUMMYFUNCTION("""COMPUTED_VALUE"""),2.0) -> 2 | B20: =IFERROR(__xludf.DUMMYFUNCTION("""COMPUTED_VALUE"""),"Las") -> Las | C20: =IFERROR(__xludf.DUMMYFUNCTION("""COMPUTED_VALUE"""),"Fabrikasi") -> Fabrikasi | R20: =IFERROR(__xludf.DUMMYFUNCTION("""COMPUTED_VALUE"""),"Konawe Utara") -> Konawe Utara

Sheet RingkasanPelatihanUPTD
A1: Jumlah Peserta Berdasarkan UPTD | D1: Jumlah Peserta Berdasarkan Kejuruan | H1: JUMLAH PESERTA PELATIHAN | K1: Jumlah Peserta Berdasarkan Pendidikan
A2: UPTD | B2: Jumlah Peserta | D2: =IFERROR(__xludf.DUMMYFUNCTION("QUERY(PelatihanUPTD!A:R, ""SELECT Col2, Col18, SUM(Col4) WHERE Col2 IS NOT NULL GROUP BY Col2, Col18 LABEL Col2 'KEJURUAN', Col18 'DAERAH', SUM(Col4) 'TOTAL PESERTA'"")"),"#VALUE!") -> #VALUE! | H2: Peserta | I2: Total | K2: =IFERROR(__xludf.DUMMYFUNCTION("QUERY(ARRAYFORMULA({PelatihanUPTD!R:R , IF(ISNUMBER(PelatihanUPTD!G:K), PelatihanUPTD!G:K, 0)}), ""SELECT Col1, SUM(Col2), SUM(Col3), SUM(Col4), SUM(Col5), SUM(Col6) WHERE Col1 IS NOT NULL GROUP BY Col1 LABEL Col1 'DAERAH', SUM(Col2) 'Sarjana', "&"SUM(Col3) 'Diploma', SUM(Col4) 'SMA / SMK', SUM(Col5) 'SMP', SUM(Col6) 'SD'"", 1)"),"DAERAH") -> DAERAH | L2: =IFERROR(__xludf.DUMMYFUNCTION("""COMPUTED_VALUE"""),"Sarjana") -> Sarjana | M2: =IFERROR(__xludf.DUMMYFUNCTION("""COMPUTED_VALUE"""),"Diploma") -> Diploma | N2: =IFERROR(__xludf.DUMMYFUNCTION("""COMPUTED_VALUE"""),"SMA / SMK") -> SMA / SMK | O2: =IFERROR(__xludf.DUMMYFUNCTION("""COMPUTED_VALUE"""),"SMP") -> SMP | P2: =IFERROR(__xludf.DUMMYFUNCTION("""COMPUTED_VALUE"""),"SD") -> SD | S2: =IFERROR(__xludf.DUMMYFUNCTION("QUERY(ARRAYFORMULA({PelatihanUPTD!R:R , IF(ISNUMBER(PelatihanUPTD!M:Q), PelatihanUPTD!M:Q, 0)}), ""SELECT Col1, SUM(Col2), SUM(Col3), SUM(Col4), SUM(Col5), SUM(Col6) WHERE Col1 IS NOT NULL GROUP BY Col1 LABEL Col1 'DAERAH', SUM(Col2) '17-24', S"&"UM(Col3) '25-28', SUM(Col4) '29-34', SUM(Col5) '35-40', SUM(Col6) '41 keatas'"", 1)"),"DAERAH") -> DAERAH | T2: =IFERROR(__xludf.DUMMYFUNCTION("""COMPUTED_VALUE"""),"17-24") -> 17-24 | U2: =IFERROR(__xludf.DUMMYFUNCTION("""COMPUTED_VALUE"""),"25-28") -> 25-28 | V2: =IFERROR(__xludf.DUMMYFUNCTION("""COMPUTED_VALUE"""),"29-34") -> 29-34 | W2: =IFERROR(__xludf.DUMMYFUNCTION("""COMPUTED_VALUE"""),"35-40") -> 35-40 | X2: =IFERROR(__xludf.DUMMYFUNCTION("""COMPUTED_VALUE"""),"41 keatas") -> 41 keatas
A3: BLK Kolaka | B3: =SUMIF(PelatihanUPTD!$R$2:$R1000, SUBSTITUTE(A3, "BLK ", ""), PelatihanUPTD!$D$2:$D1000) -> 0 | H3: Laki-Laki | I3: =sum(PelatihanUPTD!F2:F1000) -> 0 | K3: =IFERROR(__xludf.DUMMYFUNCTION("""COMPUTED_VALUE"""),"Kolaka") -> Kolaka | L3: =IFERROR(__xludf.DUMMYFUNCTION("""COMPUTED_VALUE"""),0.0) -> 0 | M3: =IFERROR(__xludf.DUMMYFUNCTION("""COMPUTED_VALUE"""),0.0) -> 0 | N3: =IFERROR(__xludf.DUMMYFUNCTION("""COMPUTED_VALUE"""),0.0) -> 0 | O3: =IFERROR(__xludf.DUMMYFUNCTION("""COMPUTED_VALUE"""),0.0) -> 0 | P3: =IFERROR(__xludf.DUMMYFUNCTION("""COMPUTED_VALUE"""),0.0) -> 0 | S3: =IFERROR(__xludf.DUMMYFUNCTION("""COMPUTED_VALUE"""),"Kolaka") -> Kolaka | T3: =IFERROR(__xludf.DUMMYFUNCTION("""COMPUTED_VALUE"""),0.0) -> 0 | U3: =IFERROR(__xludf.DUMMYFUNCTION("""COMPUTED_VALUE"""),0.0) -> 0 | V3: =IFERROR(__xludf.DUMMYFUNCTION("""COMPUTED_VALUE"""),0.0) -> 0 | W3: =IFERROR(__xludf.DUMMYFUNCTION("""COMPUTED_VALUE"""),0.0) -> 0 | X3: =IFERROR(__xludf.DUMMYFUNCTION("""COMPUTED_VALUE"""),0.0) -> 0
A4: BLK Kolaka Utara | B4: =SUMIF(PelatihanUPTD!$R$2:$R1000, SUBSTITUTE(A4, "BLK ", ""), PelatihanUPTD!$D$2:$D1000) -> 0 | H4: Perempuan | I4: =sum(PelatihanUPTD!E2:E1000) -> 0 | K4: =IFERROR(__xludf.DUMMYFUNCTION("""COMPUTED_VALUE"""),"Kolaka Utara") -> Kolaka Utara | L4: =IFERROR(__xludf.DUMMYFUNCTION("""COMPUTED_VALUE"""),0.0) -> 0 | M4: =IFERROR(__xludf.DUMMYFUNCTION("""COMPUTED_VALUE"""),0.0) -> 0 | N4: =IFERROR(__xludf.DUMMYFUNCTION("""COMPUTED_VALUE"""),0.0) -> 0 | O4: =IFERROR(__xludf.DUMMYFUNCTION("""COMPUTED_VALUE"""),0.0) -> 0 | P4: =IFERROR(__xludf.DUMMYFUNCTION("""COMPUTED_VALUE"""),0.0) -> 0 | S4: =IFERROR(__xludf.DUMMYFUNCTION("""COMPUTED_VALUE"""),"Kolaka Utara") -> Kolaka Utara | T4: =IFERROR(__xludf.DUMMYFUNCTION("""COMPUTED_VALUE"""),0.0) -> 0 | U4: =IFERROR(__xludf.DUMMYFUNCTION("""COMPUTED_VALUE"""),0.0) -> 0 | V4: =IFERROR(__xludf.DUMMYFUNCTION("""COMPUTED_VALUE"""),0.0) -> 0 | W4: =IFERROR(__xludf.DUMMYFUNCTION("""COMPUTED_VALUE"""),0.0) -> 0 | X4: =IFERROR(__xludf.DUMMYFUNCTION("""COMPUTED_VALUE"""),0.0) -> 0
